ERROR:asyncio:Task exception was never retrieved
future: <Task finished name='Task-10' coro=<Dispatcher._process_polling_updates() done, defined at /home/jatx/bot_final/env/lib/python3.8/site-packages/aiogram/dispatcher/dispatcher.py:380> exception=KeyError('count')>
Traceback (most recent call last):
  File "/home/jatx/bot_final/env/lib/python3.8/site-packages/aiogram/dispatcher/dispatcher.py", line 388, in _process_polling_updates
    for responses in itertools.chain.from_iterable(await self.process_updates(updates, fast)):
  File "/home/jatx/bot_final/env/lib/python3.8/site-packages/aiogram/dispatcher/dispatcher.py", line 225, in process_updates
    return await asyncio.gather(*tasks)
  File "/home/jatx/bot_final/env/lib/python3.8/site-packages/aiogram/dispatcher/handler.py", line 117, in notify
    response = await handler_obj.handler(*args, **partial_data)
  File "/home/jatx/bot_final/env/lib/python3.8/site-packages/aiogram/dispatcher/dispatcher.py", line 246, in process_update
    return await self.message_handlers.notify(update.message)
  File "/home/jatx/bot_final/env/lib/python3.8/site-packages/aiogram/dispatcher/handler.py", line 117, in notify
    response = await handler_obj.handler(*args, **partial_data)
  File "bothandlers_pi.py", line 217, in question_and_multiple_followers
    await checking_message(message.chat.id)
  File "bothandlers_pi.py", line 46, in checking_message
    count_child = bot_server.get_count_child(cur_mes['id'])
  File "/home/jatx/bot_final/FogstreamBot/telegrambot/botserver.py", line 257, in get_count_child
    return r.json()["count"]
KeyError: 'count'
ERROR:asyncio:Task exception was never retrieved
future: <Task finished name='Task-17' coro=<Dispatcher._process_polling_updates() done, defined at /home/jatx/bot_final/env/lib/python3.8/site-packages/aiogram/dispatcher/dispatcher.py:380> exception=JSONDecodeError('Expecting value: line 1 column 1 (char 0)')>
Traceback (most recent call last):
  File "/home/jatx/bot_final/env/lib/python3.8/site-packages/aiogram/dispatcher/dispatcher.py", line 388, in _process_polling_updates
    for responses in itertools.chain.from_iterable(await self.process_updates(updates, fast)):
  File "/home/jatx/bot_final/env/lib/python3.8/site-packages/aiogram/dispatcher/dispatcher.py", line 225, in process_updates
    return await asyncio.gather(*tasks)
  File "/home/jatx/bot_final/env/lib/python3.8/site-packages/aiogram/dispatcher/handler.py", line 117, in notify
    response = await handler_obj.handler(*args, **partial_data)
  File "/home/jatx/bot_final/env/lib/python3.8/site-packages/aiogram/dispatcher/dispatcher.py", line 246, in process_update
    return await self.message_handlers.notify(update.message)
  File "/home/jatx/bot_final/env/lib/python3.8/site-packages/aiogram/dispatcher/handler.py", line 117, in notify
    response = await handler_obj.handler(*args, **partial_data)
  File "bothandlers_pi.py", line 146, in cmd_start
    await checking_message(message.chat.id)
  File "bothandlers_pi.py", line 46, in checking_message
    count_child = bot_server.get_count_child(cur_mes['id'])
  File "/home/jatx/bot_final/FogstreamBot/telegrambot/botserver.py", line 257, in get_count_child
    return r.json()["count"]
  File "/home/jatx/bot_final/env/lib/python3.8/site-packages/requests/models.py", line 900, in json
    return complexjson.loads(self.text, **kwargs)
  File "/usr/lib/python3.8/json/__init__.py", line 357, in loads
    return _default_decoder.decode(s)
  File "/usr/lib/python3.8/json/decoder.py", line 337, in decode
    obj, end = self.raw_decode(s, idx=_w(s, 0).end())
  File "/usr/lib/python3.8/json/decoder.py", line 355, in raw_decode
    raise JSONDecodeError("Expecting value", s, err.value) from None
json.decoder.JSONDecodeError: Expecting value: line 1 column 1 (char 0)
ERROR:asyncio:Task exception was never retrieved
future: <Task finished name='Task-77' coro=<Dispatcher._process_polling_updates() done, defined at /home/jatx/bot_final/env/lib/python3.8/site-packages/aiogram/dispatcher/dispatcher.py:380> exception=KeyError('message')>
Traceback (most recent call last):
  File "/home/jatx/bot_final/env/lib/python3.8/site-packages/aiogram/dispatcher/dispatcher.py", line 388, in _process_polling_updates
    for responses in itertools.chain.from_iterable(await self.process_updates(updates, fast)):
  File "/home/jatx/bot_final/env/lib/python3.8/site-packages/aiogram/dispatcher/dispatcher.py", line 225, in process_updates
    return await asyncio.gather(*tasks)
  File "/home/jatx/bot_final/env/lib/python3.8/site-packages/aiogram/dispatcher/handler.py", line 117, in notify
    response = await handler_obj.handler(*args, **partial_data)
  File "/home/jatx/bot_final/env/lib/python3.8/site-packages/aiogram/dispatcher/dispatcher.py", line 246, in process_update
    return await self.message_handlers.notify(update.message)
  File "/home/jatx/bot_final/env/lib/python3.8/site-packages/aiogram/dispatcher/handler.py", line 117, in notify
    response = await handler_obj.handler(*args, **partial_data)
  File "bothandlers_pi.py", line 213, in question_and_multiple_followers
    bot_server.get_next_fullmessage(message.chat.id,
  File "/home/jatx/bot_final/FogstreamBot/telegrambot/botserver.py", line 239, in get_next_fullmessage
    r_options = self.get_options_answers(r_message["message"]["id"])
KeyError: 'message'
